Workbook

Sheet Rapot
A1: Laporan Hasil Belajar Peserta Didik
A2: HOMESCHOOLING TUNAS KARYA BANGSA
A3: NPSN : P 9908807 | N3: TERAKREDITASI : A
A6: Nama | B6: : | K6: Kelas | O6: :
A7: NIS/NISN | B7: : | K7: Semester | O7: :
A8: Program | B8: : | K8: Tahun Pembelajaran | O8: :
A10: DATA ABSENSI PESERTA DIDIK
A11: Mata Pelajaran | B11: Jumlah Sesi Pada Bulan | O11: Total Sesi
B12: Juli | D12: Agustus | F12: September | H12: Oktober | K12: November | M12: Desember
A13: Pendidikan Agama
A14: PKN
A15: Bahasa Indonesia
A16: Bahasa Inggris
A17: Matematika
A18: IPA
A19: IPS
A20: TIK
A21: SBK
A22: PJOK
A23: JUMLAH
A25: DAFTAR NILAI PESERTA DIDIK
A27: Mata Pelajaran | B27: Penilaian Harian | F27: Tugas/PR | J27: ATS | K27: SAS | L27: Nilai Rapor | M27: Guru Bidang Studi
B28: 1 | C28: 2 | D28: 3 | E28: 4 | F28: 1 | G28: 2 | H28: 3 | I28: 4
A29: Pendidikan Agama
A30: PKN
A31: Bahasa Indonesia
A32: Bahasa Inggris
A33: Matematika
A34: IPA
A35: IPS
A36: TIK
A37: SBK
A38: PJOK
A40: Jakarta, 23 Desember 2025
B41: Mengetahui, | N41: Dibuat oleh,
B42: Ketua Litbang HS-TKB | N42: Wali Kelas SMP
B49: () | N49: ()

Sheet Deskripsi
A1: Laporan Hasil Belajar Peserta Didik
A2: HOMESCHOOLING TUNAS KARYA BANGSA
A3: NPSN : P 9908807 | I3: TERAKREDITASI : A
A5: LAPORAN HASIL BELAJAR SISWA
A7: Nama Siswa | C7: :
A8: NIS/NISN | C8: :
A9: Kelas | C9: :
A10: Semester | C10: :
A11: Tahun Pelajaran | C11: :
A12: Program | C12: : | L12: :
A14: A. NILAI SIKAP
A15: No | B15: Aspek Penilaian | C15: Deskripsi
A16: 1
A17: 2
A18: Rata-Rata Nilai Sikap | C18: BAIK
A20: B. | B20: NILAI PENGETAHUAN DAN KETERAMPILAN
A21: No | B21: Mata Pelajaran | C21: KKM | D21: Pengetahuan | G21: Keterampilan
D22: Nilai | E22: Predikat | F22: Deskripsi | G22: Nilai | H22: Predikat | I22: Deskripsi
A23: 1 | B23: Pendidikan Agama dan Budi Pekerti | C23: 75 | G23: 85
A24: 2 | B24: Pendidikan Pancasila dan Kewarganegaraan | C24: 75 | G24: 84
A25: 3 | B25: Bahasa Indonesia | C25: 75 | G25: 80
A26: 4 | B26: Bahasa Inggris | C26: 75 | G26: 85
A27: 5 | B27: Matematika | C27: 75 | G27: 88
A28: 6 | B28: IPA | C28: 75 | G28: 85
A29: 7 | B29: IPS | C29: 75 | G29: 84
A30: 8 | B30: TIK | C30: 75 | G30: 86
A31: 9 | B31: SBK | C31: 75 | G31: 80
A32: 10 | B32: PJOK | C32: 75 | G32: 84
A33: Total Nilai
A34: Nilai Rata- Rata
B36: Absensi | G36: Kepribadian
B37: Sakit | C37: - | G37: Kedisiplinan | I37: A / B / C / D *)
B38: Izin | C38: - | G38: Kerapihan | I38: A / B / C / D *)
B39: Alpa | C39: - | G39: Kerajinan | I39: A / B / C / D *)
G40: Kesopanan | I40: A / B / C / D *)
B42: Mengetahui, | I42: Jakarta, 23 Desember 2025
B43: Orang Tua/Wali | I43: Wali Kelas
B48: ( ) | I48: ( )
A50: Kepala Sekolah
A51: HS-Tunas Karya Bangsa
...

Sheet Keterangan Nilai
A1: Laporan Hasil Belajar Peserta Didik
A2: HOMESCHOOLING TUNAS KARYA BANGSA
A3: NPSN : P 9908807 | H3: TERAKREDITASI : A
A6: Nama | B6: : | G6: Kelas | I6: :
A7: NIS/NISN | B7: : | G7: Semester | I7: :
A8: Program | B8: : | G8: Tahun Pembelajaran | I8: :
A10: CAPAIAN PEMBELAJARAN
A12: Mata Pelajaran | B12: Pemaparan Materi | D12: Hasil Pembelajaran | I12: Keterangan
D13: Penilaian Harian | E13: Asesmen Tengah Semester | G13: Sumatif Akhir Semester
A14: Pendidikan Agama | B14: Terpenuhi | D14: =IF(Rapot!S29>85,"Sangat Baik",IF(Rapot!S29>72,"Baik",IF(Rapot!S29>59,"Cukup","Kurang"))) -> Kurang | E14: =IF(Rapot!J29>85,"Sangat Baik",IF(Rapot!J29>72,"Baik",IF(Rapot!J29>59,"Cukup","Kurang"))) -> Kurang | G14: =IF(Rapot!L29>85,"Sangat Baik",IF(Rapot!L29>72,"Baik",IF(Rapot!L29>59,"Cukup","Kurang"))) -> Kurang | I14: Terlampaui
A15: PKN | B15: Terpenuhi | D15: =IF(Rapot!S30>85,"Sangat Baik",IF(Rapot!S30>72,"Baik",IF(Rapot!S30>59,"Cukup","Kurang"))) -> Kurang | E15: =IF(Rapot!J30>85,"Sangat Baik",IF(Rapot!J30>72,"Baik",IF(Rapot!J30>59,"Cukup","Kurang"))) -> Kurang | G15: =IF(Rapot!L30>85,"Sangat Baik",IF(Rapot!L30>72,"Baik",IF(Rapot!L30>59,"Cukup","Kurang"))) -> Kurang | I15: Terlampaui
A16: Bahasa Indonesia | B16: Terpenuhi | D16: =IF(Rapot!S31>85,"Sangat Baik",IF(Rapot!S31>72,"Baik",IF(Rapot!S31>59,"Cukup","Kurang"))) -> Kurang | E16: =IF(Rapot!J31>85,"Sangat Baik",IF(Rapot!J31>72,"Baik",IF(Rapot!J31>59,"Cukup","Kurang"))) -> Kurang | G16: =IF(Rapot!L31>85,"Sangat Baik",IF(Rapot!L31>72,"Baik",IF(Rapot!L31>59,"Cukup","Kurang"))) -> Kurang | I16: Terlampaui
A17: Bahasa Inggris | B17: Terpenuhi | D17: =IF(Rapot!S32>85,"Sangat Baik",IF(Rapot!S32>72,"Baik",IF(Rapot!S32>59,"Cukup","Kurang"))) -> Kurang | E17: =IF(Rapot!J32>85,"Sangat Baik",IF(Rapot!J32>72,"Baik",IF(Rapot!J32>59,"Cukup","Kurang"))) -> Kurang | G17: =IF(Rapot!L32>85,"Sangat Baik",IF(Rapot!L32>72,"Baik",IF(Rapot!L32>59,"Cukup","Kurang"))) -> Kurang | I17: Terlampaui
A18: Matematika | B18: Terpenuhi | D18: =IF(Rapot!S33>85,"Sangat Baik",IF(Rapot!S33>72,"Baik",IF(Rapot!S33>59,"Cukup","Kurang"))) -> Kurang | E18: =IF(Rapot!J33>85,"Sangat Baik",IF(Rapot!J33>72,"Baik",IF(Rapot!J33>59,"Cukup","Kurang"))) -> Kurang | G18: =IF(Rapot!L33>85,"Sangat Baik",IF(Rapot!L33>72,"Baik",IF(Rapot!L33>59,"Cukup","Kurang"))) -> Kurang | I18: Terlampaui
A19: IPA | B19: Terpenuhi | D19: =IF(Rapot!S34>85,"Sangat Baik",IF(Rapot!S34>72,"Baik",IF(Rapot!S34>59,"Cukup","Kurang"))) -> Kurang | E19: =IF(Rapot!J34>85,"Sangat Baik",IF(Rapot!J34>72,"Baik",IF(Rapot!J34>59,"Cukup","Kurang"))) -> Kurang | G19: =IF(Rapot!L34>85,"Sangat Baik",IF(Rapot!L34>72,"Baik",IF(Rapot!L34>59,"Cukup","Kurang"))) -> Kurang | I19: Terlampaui
A20: IPS | B20: Terpenuhi | D20: =IF(Rapot!S35>85,"Sangat Baik",IF(Rapot!S35>72,"Baik",IF(Rapot!S35>59,"Cukup","Kurang"))) -> Kurang | E20: =IF(Rapot!J35>85,"Sangat Baik",IF(Rapot!J35>72,"Baik",IF(Rapot!J35>59,"Cukup","Kurang"))) -> Kurang | G20: =IF(Rapot!L35>85,"Sangat Baik",IF(Rapot!L35>72,"Baik",IF(Rapot!L35>59,"Cukup","Kurang"))) -> Kurang | I20: Terlampaui
A21: TIK | B21: Terpenuhi | D21: =IF(Rapot!S36>85,"Sangat Baik",IF(Rapot!S36>72,"Baik",IF(Rapot!S36>59,"Cukup","Kurang"))) -> Kurang | E21: =IF(Rapot!J36>85,"Sangat Baik",IF(Rapot!J36>72,"Baik",IF(Rapot!J36>59,"Cukup","Kurang"))) -> Kurang | G21: =IF(Rapot!L36>85,"Sangat Baik",IF(Rapot!L36>72,"Baik",IF(Rapot!L36>59,"Cukup","Kurang"))) -> Kurang | I21: Terlampaui
A22: SBK | B22: Terpenuhi | D22: =IF(Rapot!S37>85,"Sangat Baik",IF(Rapot!S37>72,"Baik",IF(Rapot!S37>59,"Cukup","Kurang"))) -> Kurang | E22: =IF(Rapot!J37>85,"Sangat Baik",IF(Rapot!J37>72,"Baik",IF(Rapot!J37>59,"Cukup","Kurang"))) -> Kurang | G22: =IF(Rapot!L37>85,"Sangat Baik",IF(Rapot!L37>72,"Baik",IF(Rapot!L37>59,"Cukup","Kurang"))) -> Kurang | I22: Terlampaui
A23: PJOK | B23: Terpenuhi | D23: =IF(Rapot!S38>85,"Sangat Baik",IF(Rapot!S38>72,"Baik",IF(Rapot!S38>59,"Cukup","Kurang"))) -> Kurang | E23: =IF(Rapot!J38>85,"Sangat Baik",IF(Rapot!J38>72,"Baik",IF(Rapot!J38>59,"Cukup","Kurang"))) -> Kurang | G23: =IF(Rapot!L38>85,"Sangat Baik",IF(Rapot!L38>72,"Baik",IF(Rapot!L38>59,"Cukup","Kurang"))) -> Kurang | I23: Terlampaui
A25: Keterangan
A26: Nilai | B26: Huruf | C26: Keterangan
A27: 86-98 | B27: A | C27: Sangat Baik
A28: 73-85 | B28: B | C28: Baik
A29: 60-72 | B29: C | C29: Cukup
A30: <59 | B30: D | C30: Kurang
A32: Jakarta, 23 Desember 2025
B34: Mengetahui, | G34: Dibuat oleh,
B35: Ketua Litbang HS-TKB | G35: Wali Kelas SMP
B40: () | G40: ()

Sheet Safira
A1: Nama Siswa | B1: : Safira | G1: Kelas | I1: : IX SMP
A2: NIS/NISN | B2: : B-T-00455-22/0109620105 | G2: Semester | I2: : Ganjil (I)
A3: Program | B3: : Komunitas | G3: Tahun Pelajaran | I3: : 2024/2025
A6: DATA ABSENSI SISWA
A8: Mata Pelajaran | B8: Jumlah Sesi Pada Bulan | H8: Total Sesi
B9: Juli | C9: Agustus | D9: September | E9: Oktober | F9: November | G9: Desember
A10: AGAMA | H10: =SUM(B10:G10) -> 0
A11: PKN | H11: =SUM(B11:G11) -> 0
A12: B. INDONESIA | H12: =SUM(B12:G12) -> 0
A13: B. INGGRIS | H13: =SUM(B13:G13) -> 0
A14: MATEMATIKA | H14: =SUM(B14:G14) -> 0
A15: IPA | H15: =SUM(B15:G15) -> 0
A16: IPS | H16: =SUM(B16:G16) -> 0
A17: TIK | H17: =SUM(B17:G17) -> 0
A18: SBK | H18: =SUM(B18:G18) -> 0
A19: PJOK | H19: =SUM(B19:G19) -> 0
A20: JUMLAH | B20: =SUM(B10:B16) -> 0 | C20: =SUM(C10:C16) -> 0 | D20: =SUM(D10:D16) -> 0 | E20: =SUM(E10:E16) -> 0 | F20: =SUM(F10:F16) -> 0 | G20: =SUM(G10:G16) -> 0 | H20: =SUM(B20:G20) -> 0
A22: DAFTAR NILAI SISWA
A24: Mata Pelajaran | B24: Penilaian Harian | F24: Tugas/PR | I24: ATS | J24: SAS | K24: Nilai Rapor | L24: Guru Bidang Studi
B25: 1 | C25: 2 | D25: 3 | E25: 4 | F25: 1 | G25: 2 | H25: 3
A26: AGAMA | L26: Nafisah Al-Khairiyyah S.Pd
A27: PKN | L27: Nico, S.Pd
A28: B.INDONESIA | L28: Desi Astriana S, S.Pd
A29: B. INGGRIS | L29: Anaqi
A30: MATEMATIKA | L30: Evi Fitri, S.Si
A31: IPA | B31: 85 | C31: 80 | D31: 80 | F31: 90 | G31: 86 | H31: 85 | I31: 76 | L31: Eliza Ernita, S.Pd
A32: IPS | L32: Fina Firyal F, S.Pd
A33: TIK | L33: Nico, S.Pd
A34: SBK | L34: Nico, S.Pd
A35: PJOK | L35: Nico, S.Pd
A37: PREDIKAT HASIL PEMBELAJARAN
A39: No | B39: Mata Pelajaran | C39: Pemaparan Materi | D39: Hasil Pembelajaran | G39: Keterangan
D40: Penilaian Harian | E40: Asesmen Tengah Semester | F40: Sumatif Akhir Semester
A41: 1. | B41: AGAMA | C41: Terpenuhi | G41: Terlampaui
A42: 2. | B42: PKN | C42: Terpenuhi | G42: Terlampaui
A43: 3. | B43: B. INDONESIA | C43: Terpenuhi | G43: Terlampaui
A44: 4. | B44: B. INGGRIS | C44: Terpenuhi | G44: Terlampaui
A45: 5. | B45: MATEMATIKA | C45: Terpenuhi | G45: Terlampaui
A46: 6. | B46: IPA | C46: Terpenuhi | G46: Terlampaui
A47: 8. | B47: IPS | C47: Terpenuhi | G47: Terlampaui
...

Sheet Amanda
A1: Nama Siswa | B1: : Amanda | G1: Kelas | I1: : IX SMP
A2: NIS/NISN | B2: : B-T-00455-22/0109620105 | G2: Semester | I2: : Ganjil (I)
A3: Program | B3: : Komunitas | G3: Tahun Pelajaran | I3: : 2024/2025
A6: DATA ABSENSI SISWA
A8: Mata Pelajaran | B8: Jumlah Sesi Pada Bulan | H8: Total Sesi
B9: Juli | C9: Agustus | D9: September | E9: Oktober | F9: November | G9: Desember
A10: AGAMA | H10: =SUM(B10:G10) -> 0
A11: PKN | H11: =SUM(B11:G11) -> 0
A12: B. INDONESIA | H12: =SUM(B12:G12) -> 0
A13: B. INGGRIS | H13: =SUM(B13:G13) -> 0
A14: MATEMATIKA | H14: =SUM(B14:G14) -> 0
A15: IPA | H15: =SUM(B15:G15) -> 0
A16: IPS | H16: =SUM(B16:G16) -> 0
A17: TIK | H17: =SUM(B17:G17) -> 0
A18: SBK | H18: =SUM(B18:G18) -> 0
A19: PJOK | H19: =SUM(B19:G19) -> 0
A20: JUMLAH | B20: =SUM(B10:B16) -> 0 | C20: =SUM(C10:C16) -> 0 | D20: =SUM(D10:D16) -> 0 | E20: =SUM(E10:E16) -> 0 | F20: =SUM(F10:F16) -> 0 | G20: =SUM(G10:G16) -> 0 | H20: =SUM(B20:G20) -> 0
A22: DAFTAR NILAI SISWA
A24: Mata Pelajaran | B24: Penilaian Harian | F24: Tugas/PR | I24: ATS | J24: SAS | K24: Nilai Rapor | L24: Guru Bidang Studi
B25: 1 | C25: 2 | D25: 3 | E25: 4 | F25: 1 | G25: 2 | H25: 3
A26: AGAMA
A27: PKN | L27: Nico, S.Pd
A28: B.INDONESIA | L28: Desi Astriana S, S.Pd
A29: B. INGGRIS | L29: Anaqi
A30: MATEMATIKA | L30: Evi Fitri, S.Si
A31: IPA | B31: 78 | C31: 80 | D31: 85 | F31: 85 | H31: 88 | I31: 80 | L31: Eliza Ernita, S.Pd
A32: IPS | L32: Fina Firyal F, S.Pd
A33: TIK | L33: Nico, S.Pd
A34: SBK | L34: Nico, S.Pd
A35: PJOK | L35: Nico, S.Pd
A37: PREDIKAT HASIL PEMBELAJARAN
A39: No | B39: Mata Pelajaran | C39: Pemaparan Materi | D39: Hasil Pembelajaran | G39: Keterangan
D40: Penilaian Harian | E40: Asesmen Tengah Semester | F40: Sumatif Akhir Semester
A41: 1. | B41: AGAMA | C41: Terpenuhi | G41: Terlampaui
A42: 2. | B42: PKN | C42: Terpenuhi | G42: Terlampaui
A43: 3. | B43: B. INDONESIA | C43: Terpenuhi | G43: Terlampaui
A44: 4. | B44: B. INGGRIS | C44: Terpenuhi | G44: Terlampaui
A45: 5. | B45: MATEMATIKA | C45: Terpenuhi | G45: Terlampaui
A46: 6. | B46: IPA | C46: Terpenuhi | G46: Terlampaui
A47: 8. | B47: IPS | C47: Terpenuhi | G47: Terlampaui
...
